[nltk_data] Downloading package punkt to /home/joel_jang/nltk_data...
[nltk_data]   Package punkt is already up-to-date!
GPU available: True, used: True
TPU available: False, using: 0 TPU cores
IPU available: False, using: 0 IPUs
initializing distributed: GLOBAL_RANK: 0, MEMBER: 1/7
----------------------------------------------------------------------------------------------------
distributed_backend=nccl
All distributed processes registered. Starting with 7 processes
----------------------------------------------------------------------------------------------------
LOCAL_RANK: 0 - CUDA_VISIBLE_DEVICES: [0,1,2,3,4,5,6]
  | Name  | Type                       | Params
-----------------------------------------------------
0 | model | T5ForConditionalGeneration | 2.8 B
-----------------------------------------------------
2.8 B     Trainable params
0         Non-trainable params
2.8 B     Total params
11,399.029Total estimated model params size (MB)
Validation sanity check: 0it [00:00, ?it/s]Length of dataset retrieving is.. 200
Validation sanity check:   0%|                                                    | 0/2 [00:00<?, ?it/s]
WARNING:datasets.builder:Found cached dataset cosmos_qa (/home/joel_jang/.cache/huggingface/datasets/cosmos_qa/default/0.1.0/3e18538cbfdb2c04189b16642715f0f6da3e97ed5df0aadcec3641245b2cf157)
100%|████████████████████████████████████████████████████████████████████| 3/3 [00:00<00:00, 587.05it/s]
WARNING:datasets.arrow_dataset:Loading cached shuffled indices for dataset at /home/joel_jang/.cache/huggingface/datasets/cosmos_qa/default/0.1.0/3e18538cbfdb2c04189b16642715f0f6da3e97ed5df0aadcec3641245b2cf157/cache-780ded7a9fe6758d.arrow
/home/joel_jang/miniconda3/envs/zeroshot/lib/python3.8/site-packages/pytorch_lightning/utilities/data.py:56: UserWarning: Trying to infer the `batch_size` from an ambiguous collection. The batch size we found is 4. To avoid any miscalculations, use `self.log(..., batch_size=batch_size)`.
Validation sanity check: 100%|████████████████████████████████████████████| 2/2 [00:07<00:00,  3.32s/it]agg_score is tensor(0.0893, device='cuda:0') 0
enter
###############################
{'answer0': 'None of the above choices .', 'answer1': 'I could get hurt on the job', 'answer2': 'I could get fired .', 'answer3': 'I could buy a lot of groceries .', 'context': "do i have a job yet ? no . ... but i have job training ! ! ! it sounds totally miraculous , i know , but my application for certification has been picked up , i ' ve been snuck through the backdoor at the last minute , and nancy ( three cheers for nancy ! ! ! )", 'id': '3WA2XVDZEMF0M64ATQQICXK8O3J6EZ##3A4TN5196LG48H27JLHT8K5JNZACHN##A2JY56TZCEPK3J##Blog_706890##q1_a2##38RHULDV9YDAWQL2GRTDV6HD5EIIWH', 'label': 3, 'question': 'What may happen if i found a job ?'}
###############################
Length of dataset retrieving is.. 28
Training: 0it [00:00, ?it/s]
WARNING:datasets.builder:Found cached dataset cosmos_qa (/home/joel_jang/.cache/huggingface/datasets/cosmos_qa/default/0.1.0/3e18538cbfdb2c04189b16642715f0f6da3e97ed5df0aadcec3641245b2cf157)
100%|████████████████████████████████████████████████████████████████████| 3/3 [00:00<00:00, 420.99it/s]
/home/joel_jang/miniconda3/envs/zeroshot/lib/python3.8/site-packages/pytorch_lightning/trainer/data_loading.py:394: UserWarning: The number of training samples (1) is smaller than the logging interval Trainer(log_every_n_steps=50). Set a lower value for log_every_n_steps if you want to see logs for the training epoch.

Epoch 0:  11%|████                                 | 1/9 [00:13<01:45, 13.21s/it, loss=1.48, v_num=m7c6]



Validating:  88%|█████████████████████████████████████████████████▉       | 7/8 [00:12<00:00,  1.13it/s]
/home/joel_jang/miniconda3/envs/zeroshot/lib/python3.8/site-packages/pytorch_lightning/utilities/data.py:56: UserWarning: Trying to infer the `batch_size` from an ambiguous collection. The batch size we found is 1. To avoid any miscalculations, use `self.log(..., batch_size=batch_size)`.

enterating: 100%|█████████████████████████████████████████████████████████| 8/8 [00:12<00:00,  1.19it/s]
Epoch 0: 100%|█████████████████████████████████████| 9/9 [00:35<00:00,  3.93s/it, loss=1.48, v_num=m7c6]
Traceback (most recent call last):
  File "/home/joel_jang/miniconda3/envs/zeroshot/lib/python3.8/site-packages/torch/serialization.py", line 379, in save
    _save(obj, opened_zipfile, pickle_module, pickle_protocol)
  File "/home/joel_jang/miniconda3/envs/zeroshot/lib/python3.8/site-packages/torch/serialization.py", line 499, in _save
    zip_file.write_record(name, storage.data_ptr(), num_bytes)
KeyboardInterrupt
During handling of the above exception, another exception occurred:
Traceback (most recent call last):
  File "run.py", line 222, in <module>
    trainer.fit(model)
  File "/home/joel_jang/miniconda3/envs/zeroshot/lib/python3.8/site-packages/pytorch_lightning/trainer/trainer.py", line 735, in fit
    self._call_and_handle_interrupt(
  File "/home/joel_jang/miniconda3/envs/zeroshot/lib/python3.8/site-packages/pytorch_lightning/trainer/trainer.py", line 682, in _call_and_handle_interrupt
    return trainer_fn(*args, **kwargs)
  File "/home/joel_jang/miniconda3/envs/zeroshot/lib/python3.8/site-packages/pytorch_lightning/trainer/trainer.py", line 770, in _fit_impl
    self._run(model, ckpt_path=ckpt_path)
  File "/home/joel_jang/miniconda3/envs/zeroshot/lib/python3.8/site-packages/pytorch_lightning/trainer/trainer.py", line 1193, in _run
    self._dispatch()
  File "/home/joel_jang/miniconda3/envs/zeroshot/lib/python3.8/site-packages/pytorch_lightning/trainer/trainer.py", line 1272, in _dispatch
    self.training_type_plugin.start_training(self)
  File "/home/joel_jang/miniconda3/envs/zeroshot/lib/python3.8/site-packages/pytorch_lightning/plugins/training_type/training_type_plugin.py", line 202, in start_training
    self._results = trainer.run_stage()
  File "/home/joel_jang/miniconda3/envs/zeroshot/lib/python3.8/site-packages/pytorch_lightning/trainer/trainer.py", line 1282, in run_stage
    return self._run_train()
  File "/home/joel_jang/miniconda3/envs/zeroshot/lib/python3.8/site-packages/pytorch_lightning/trainer/trainer.py", line 1312, in _run_train
    self.fit_loop.run()
  File "/home/joel_jang/miniconda3/envs/zeroshot/lib/python3.8/site-packages/pytorch_lightning/loops/base.py", line 145, in run
    self.advance(*args, **kwargs)
  File "/home/joel_jang/miniconda3/envs/zeroshot/lib/python3.8/site-packages/pytorch_lightning/loops/fit_loop.py", line 234, in advance
    self.epoch_loop.run(data_fetcher)
  File "/home/joel_jang/miniconda3/envs/zeroshot/lib/python3.8/site-packages/pytorch_lightning/loops/base.py", line 146, in run
    self.on_advance_end()
  File "/home/joel_jang/miniconda3/envs/zeroshot/lib/python3.8/site-packages/pytorch_lightning/loops/epoch/training_epoch_loop.py", line 246, in on_advance_end
    self._run_validation()
  File "/home/joel_jang/miniconda3/envs/zeroshot/lib/python3.8/site-packages/pytorch_lightning/loops/epoch/training_epoch_loop.py", line 341, in _run_validation
    self.val_loop.run()
  File "/home/joel_jang/miniconda3/envs/zeroshot/lib/python3.8/site-packages/pytorch_lightning/loops/base.py", line 151, in run
    output = self.on_run_end()
  File "/home/joel_jang/miniconda3/envs/zeroshot/lib/python3.8/site-packages/pytorch_lightning/loops/dataloader/evaluation_loop.py", line 130, in on_run_end
    self._evaluation_epoch_end(outputs)
  File "/home/joel_jang/miniconda3/envs/zeroshot/lib/python3.8/site-packages/pytorch_lightning/loops/dataloader/evaluation_loop.py", line 235, in _evaluation_epoch_end
    model.validation_epoch_end(outputs)
  File "/home/joel_jang/seungone/Flipped-Learning/T0/T5.py", line 320, in validation_epoch_end
    torch.save(param_dict, self.args.output_dir[:-3]+'_last.pt')
  File "/home/joel_jang/miniconda3/envs/zeroshot/lib/python3.8/site-packages/torch/serialization.py", line 380, in save
    return
  File "/home/joel_jang/miniconda3/envs/zeroshot/lib/python3.8/site-packages/torch/serialization.py", line 259, in __exit__
    self.file_like.write_end_of_file()
RuntimeError: [enforce fail at inline_container.cc:300] . unexpected pos 4885851392 vs 4885851288